<?xml version="1.0" encoding="UTF-8"?>
<!-- Generated by org.testng.reporters.JUnitReportReporter -->
<testsuite hostname="Admins-MacBook-Pro.local" failures="2" tests="11" name="api.tests.TestsOrderFlow3" time="11.039" errors="0" timestamp="2024-12-15T21:59:47 IST" skipped="0">
  <testcase classname="api.tests.TestsOrderFlow3" name="testOrderFlowGenerateToken" time="3.093"/>
  <testcase classname="api.tests.TestsOrderFlow3" name="testOrderFlowCreateOrder" time="3.702"/>
  <testcase classname="api.tests.TestsOrderFlow3" name="testOrderFlowBatchAssign" time="0.272"/>
  <testcase classname="api.tests.TestsOrderFlow3" name="testOrderFlowMarkPacked" time="1.053"/>
  <testcase classname="api.tests.TestsOrderFlow3" name="testOrderFlowCreateShipment" time="1.262"/>
  <testcase classname="api.tests.TestsOrderFlow3" name="testOrderFlowDispatch" time="0.495"/>
  <testcase classname="api.tests.TestsOrderFlow3" name="testOrderFlowDeliver" time="0.144"/>
  <testcase classname="api.tests.TestsOrderFlow3" name="testOrderFlowActionCompleteQC" time="0.600"/>
  <testcase classname="api.tests.TestsOrderFlow3" name="testOrderFlowAccceptItem1QC" time="0.218"/>
  <testcase classname="api.tests.TestsOrderFlow3" name="testOrderFlowCompleteQC" time="0.090">
    <failure message="Test failed due to unexpected status code: 400" type="java.lang.AssertionError">
      <![CDATA[java.lang.AssertionError: Test failed due to unexpected status code: 400
at org.testng.Assert.fail(Assert.java:111)
at api.tests.TestsOrderFlow3.testOrderFlowCompleteQC(TestsOrderFlow3.java:200)
at java.base/jdk.internal.reflect.DirectMethodHandleAccessor.invoke(DirectMethodHandleAccessor.java:103)
at java.base/java.lang.reflect.Method.invoke(Method.java:580)
at org.testng.internal.invokers.MethodInvocationHelper.invokeMethod(MethodInvocationHelper.java:141)
at org.testng.internal.invokers.TestInvoker.invokeMethod(TestInvoker.java:686)
at org.testng.internal.invokers.TestInvoker.invokeTestMethod(TestInvoker.java:230)
at org.testng.internal.invokers.MethodRunner.runInSequence(MethodRunner.java:63)
at org.testng.internal.invokers.TestInvoker$MethodInvocationAgent.invoke(TestInvoker.java:992)
at org.testng.internal.invokers.TestInvoker.invokeTestMethods(TestInvoker.java:203)
at org.testng.internal.invokers.TestMethodWorker.invokeTestMethods(TestMethodWorker.java:154)
at org.testng.internal.invokers.TestMethodWorker.run(TestMethodWorker.java:134)
at java.base/java.util.ArrayList.forEach(ArrayList.java:1597)
at org.testng.TestRunner.privateRun(TestRunner.java:739)
at org.testng.TestRunner.run(TestRunner.java:614)
at org.testng.SuiteRunner.runTest(SuiteRunner.java:421)
at org.testng.SuiteRunner.runSequentially(SuiteRunner.java:413)
at org.testng.SuiteRunner.privateRun(SuiteRunner.java:373)
at org.testng.SuiteRunner.run(SuiteRunner.java:312)
at org.testng.SuiteRunnerWorker.runSuite(SuiteRunnerWorker.java:52)
at org.testng.SuiteRunnerWorker.run(SuiteRunnerWorker.java:95)
at org.testng.TestNG.runSuitesSequentially(TestNG.java:1274)
at org.testng.TestNG.runSuitesLocally(TestNG.java:1208)
at org.testng.TestNG.runSuites(TestNG.java:1112)
at org.testng.TestNG.run(TestNG.java:1079)
at org.testng.remote.AbstractRemoteTestNG.run(AbstractRemoteTestNG.java:115)
at org.testng.remote.RemoteTestNG.initAndRun(RemoteTestNG.java:293)
at org.testng.remote.RemoteTestNG.main(RemoteTestNG.java:91)
]]>
    </failure>
  </testcase> <!-- testOrderFlowCompleteQC -->
  <testcase classname="api.tests.TestsOrderFlow3" name="testOrderFlowIneventorySettlement" time="0.110">
    <failure message="Test failed due to unexpected status code: 400" type="java.lang.AssertionError">
      <![CDATA[java.lang.AssertionError: Test failed due to unexpected status code: 400
at org.testng.Assert.fail(Assert.java:111)
at api.tests.TestsOrderFlow3.testOrderFlowIneventorySettlement(TestsOrderFlow3.java:216)
at java.base/jdk.internal.reflect.DirectMethodHandleAccessor.invoke(DirectMethodHandleAccessor.java:103)
at java.base/java.lang.reflect.Method.invoke(Method.java:580)
at org.testng.internal.invokers.MethodInvocationHelper.invokeMethod(MethodInvocationHelper.java:141)
at org.testng.internal.invokers.TestInvoker.invokeMethod(TestInvoker.java:686)
at org.testng.internal.invokers.TestInvoker.invokeTestMethod(TestInvoker.java:230)
at org.testng.internal.invokers.MethodRunner.runInSequence(MethodRunner.java:63)
at org.testng.internal.invokers.TestInvoker$MethodInvocationAgent.invoke(TestInvoker.java:992)
at org.testng.internal.invokers.TestInvoker.invokeTestMethods(TestInvoker.java:203)
at org.testng.internal.invokers.TestMethodWorker.invokeTestMethods(TestMethodWorker.java:154)
at org.testng.internal.invokers.TestMethodWorker.run(TestMethodWorker.java:134)
at java.base/java.util.ArrayList.forEach(ArrayList.java:1597)
at org.testng.TestRunner.privateRun(TestRunner.java:739)
at org.testng.TestRunner.run(TestRunner.java:614)
at org.testng.SuiteRunner.runTest(SuiteRunner.java:421)
at org.testng.SuiteRunner.runSequentially(SuiteRunner.java:413)
at org.testng.SuiteRunner.privateRun(SuiteRunner.java:373)
at org.testng.SuiteRunner.run(SuiteRunner.java:312)
at org.testng.SuiteRunnerWorker.runSuite(SuiteRunnerWorker.java:52)
at org.testng.SuiteRunnerWorker.run(SuiteRunnerWorker.java:95)
at org.testng.TestNG.runSuitesSequentially(TestNG.java:1274)
at org.testng.TestNG.runSuitesLocally(TestNG.java:1208)
at org.testng.TestNG.runSuites(TestNG.java:1112)
at org.testng.TestNG.run(TestNG.java:1079)
at org.testng.remote.AbstractRemoteTestNG.run(AbstractRemoteTestNG.java:115)
at org.testng.remote.RemoteTestNG.initAndRun(RemoteTestNG.java:293)
at org.testng.remote.RemoteTestNG.main(RemoteTestNG.java:91)
]]>
    </failure>
  </testcase> <!-- testOrderFlowIneventorySettlement -->
</testsuite> <!-- api.tests.TestsOrderFlow3 -->
